<!DOCTYPE html>
<html xmlns="http://www.w3.org/1999/xhtml"><head><title>Cwe_248 (cwe_checker_core.Cwe_checker_core.Cwe_248)</title><link rel="stylesheet" href="../../../odoc.css"/><meta charset="utf-8"/><meta name="viewport" content="width=device-width,initial-scale=1.0"/><script src="../../../highlight.pack.js"></script><script>hljs.initHighlightingOnLoad();</script></head><body><div class="content"><header><nav><a href="../index.html">Up</a> â€“ <a href="../../index.html">cwe_checker_core</a> &#x00BB; <a href="../index.html">Cwe_checker_core</a> &#x00BB; Cwe_248</nav><h1>Module <code>Cwe_checker_core.Cwe_248</code></h1><nav class="toc"><ul><li><a href="#how-the-check-works">How the check works</a></li><li><a href="#false-positives">False Positives</a></li><li><a href="#false-negatives">False Negatives</a></li></ul></nav></header><aside><p>This module implements a check for CWE-248: Uncaught Exception.</p><p>An uncaught exception may lead to a crash.</p><p>See <a href="https://cwe.mitre.org/data/definitions/248.html">https://cwe.mitre.org/data/definitions/248.html</a> for a detailed description.</p></aside><section><header><h2 id="how-the-check-works"><a href="#how-the-check-works" class="anchor"></a>How the check works</h2><p>The tool searches for exception throws that are reachable in the callgraph without touching a function that contains a catch block. We do not check whether a catch block can actually catch the thrown exceptions, thus we generate some false negatives.</p></header></section><section><header><h2 id="false-positives"><a href="#false-positives" class="anchor"></a>False Positives</h2><ul><li>There is no check whether a specific exception throw can be triggered or not</li></ul></header></section><section><header><h2 id="false-negatives"><a href="#false-negatives" class="anchor"></a>False Negatives</h2><ul><li>An exception that gets catched through one execution path but would not get catched through a different execution path will not get flagged.</li><li>It is not checked whether the catch block can actually catch a thrown exception or not. A catch block may only be able to catch exceptions of a specific type.</li></ul></header><dl><dt class="spec value" id="val-name"><a href="#val-name" class="anchor"></a><code><span class="keyword">val</span> name : string</code></dt><dt class="spec value" id="val-version"><a href="#val-version" class="anchor"></a><code><span class="keyword">val</span> version : string</code></dt><dt class="spec value" id="val-check_cwe"><a href="#val-check_cwe" class="anchor"></a><code><span class="keyword">val</span> check_cwe : <span>Bap.Std.program Bap.Std.term</span> <span>&#45;&gt;</span> Bap.Std.project <span>&#45;&gt;</span> <span>Bap.Std.word Bap.Std.Tid.Map.t</span> <span>&#45;&gt;</span> <span><span>string list</span> list</span> <span>&#45;&gt;</span> <span>string list</span> <span>&#45;&gt;</span> unit</code></dt></dl></section></div></body></html>